Workbook
Name _MWM_WSO_DATA: '_What Stands Out Dropdowns v3'!$B$2:$Q$267
Name _MWM_WSO_KEYS: '_What Stands Out Dropdowns v3'!$A$2:$A$267

Sheet Business Intake
A1: Business Name | B1: City | C1: State | D1: Original Category | E1: Main Category | F1: Subcategory | G1: Website or Social Media | H1: Brief Description (1–2 sentences) | I1: Vibe 1 | J1: Vibe 2 | K1: Vibe 3 | L1: Ownership 1 | M1: Ownership 2 | N1: Recommended By | O1: Notes | P1: Address | Q1: Zip Code | R1: Quick Review Preview 1 | S1: Quick Review Preview 2 | T1: Quick Review Preview 3 | U1: Verification Status
A2: The Nail Jawns | B2: Philadelphia | C2: PA | D2: Nail Salon | E2: Beauty & Personal Care | F2: Nail Salons & Nail Artists | G2: https://www.tiktok.com/@the.nail.jawns | I2: Soft Life | J2: Luxury Without The Attitude | K2: Main Character Energy | L2: Black / African American-Owned | N2: Friend | O2: Walk-ins Welcomed, Appointments preferred. | P2: 429 N. 64th St | Q2: 19151 | R2: Style Lasted | S2: Book Now | T2: Worth The Price
A3: Cherished Beauty Supply | B3: Darby | C3: PA | D3: Beauty | E3: Beauty & Personal Care | F3: Beauty Supply | G3: https://www.tiktok.com/@cherishedbeautysupply | H3: Plant-Based Hair & Skin Care. Black-Owned Beauty Supply | I3: Chill & Restore | J3: For The Culture | L3: Black / African American-Owned | N3: Friend | O3: Willing to Ship! | P3: 526 Main St | Q3: 19023 | R3: Worth The Price
A4: Angie's Eats | B4: Philadelphia | C4: PA | D4: Restaurant | E4: Food & Drink | F4: Restaurants | G4: https://www.tiktok.com/@angieslne | H4: Latin Soul Food | I4: Locals Know | J4: Take Somebody From Out of Town | L4: Latino / Hispanic-Owned | N4: Personal visit | O4: The Shrimp Alfredo with 6 wings combo is FIRE | R4: Portions With Love | S4: Seasoned Right | T4: I Sent The Group Chat
A5: ISSAAESTHETICS Beauty Salon & Barbershop | B5: Silver Spring | C5: MD | D5: Barber/Salon | E5: Beauty & Personal Care | F5: Hair Salons | G5: https://www.instagram.com/issaaestheticsbeauty | H5: Laser Hair Removal/Blow Outs/Chemical Peels and More | I5: Neighborhood Love | L5: Dominican-Owned | N5: Friend | O5: Se Habla Espanol | P5: 11409 Amherst Ave Unit A | Q5: 20902 | R5: On Time, Every Time | S5: Worth The Price
A6: Candy Clouds By Cass | B6: Santa Clara | C6: CA | D6: Restaurant | E6: Food & Drink | F6: Desserts & Sweets | G6: https://www.instagram.com/candycloudsbycass | H6: Sweet Clouds for Every Celebration! | I6: Bougie Treat | L6: Minority-Owned (general / legacy) | O6: Serving the Bay Area | R6: Sweet, Not Too Sweet | S6: Don't Sleep On This One
A7: Little Essentials | B7: New York | C7: NY | E7: Community & Nonprofit | F7: Youth Organizations | G7: https://www.littleessentials.org | H7: Little Essentials offers at-risk families living in poverty urgently needed children’s supplies and parenting education to promote the health, well-being, and safety of their children ages 0-5. Little Essentials offers at-risk families living in poverty urgently needed children’s supplies and parenting education to promote the health, well-being, and safety of their children ages 0-5. | I7: Neighborhood Love | L7: Minority-Owned (general / legacy) | O7: 80, 265 NYC Children Served 37, 628 NYC Families Helped 1, 809, 338 Diapers Distributed | P7: 63 Flushing Avenue, Bldg 131, Ste 205 | Q7: 11205 | R7: Help Was Real | S7: No Judgment
A8: Philly Barber Studios | B8: Philadelphia | C8: PA | E8: Beauty & Personal Care | F8: Barbershops | G8: https://www.instagram.com/phillybarberstudios/ | H8: From precision fade haircuts to straight razor shaving. Cutting, trimming your head to Perfection. Shampoo and conditioner, then hot towel and neck shave. | I8: Neighborhood Love | J8: For The Culture | L8: Minority-Owned (general / legacy) | O8: Good for kids, book appointment | P8: 7938 Oxford Ave | Q8: 19111 | R8: Patient With Kids | S8: Sharpest Lineup | T8: Patient With Kids
A9: AMINA | B9: Philadelphia | C9: PA | E9: Food & Drink | F9: Restaurants | G9: https://www.aminaphilly.com | H9: Amina Restaurant is a restaurant and bar in No Libs Philadelphia, serving up American Southern cuisine. Owner Felicia Wilson and Chef Partner Darryl Harmon are innovators in the Southern cuisine space. | I9: Date Night | J9: Locals Know | K9: Take Somebody From Out of Town | L9: Black / African American-Owned | M9: Woman-Owned | N9: Personal visit | O9: Saturday Brunch books Fast so make a reservation | P9: 1102 Germantown Ave | Q9: 19123 | R9: Cooks Like Home | S9: Seasoned Right | T9: Grandma Approved
A10: SOUTH | B10: Philadelphia | C10: PA | E10: Food & Drink | F10: Restaurants | G10: https://www.southjazzkitchen.com | H10: Since 2015, SOUTH has served up elevated comfort food rooted in the food of the south.At SOUTH, America’s original music meets southern heritage cuisine in Philadelphia’s Spring Garden neighborhood on Avenue of the Arts North. | I10: Date Night | J10: Late Night Vibes | K10: Locals Know | L10: Black / African American-Owned | N10: Personal visit | O10: Dressy and business casual attire are preferred. | P10: 600 N Broad St | Q10: 19130 | R10: Book This Table | S10: Don't Sleep On This One

Sheet Category Reference
A1: Main Category | B1: Subcategory | C1: Notes
A2: Food & Drink | B2: Restaurants | C2: Approved source-of-truth taxonomy
A3: Food & Drink | B3: Cafés & Coffee | C3: Approved source-of-truth taxonomy
A4: Food & Drink | B4: Bakeries | C4: Approved source-of-truth taxonomy
A5: Food & Drink | B5: Desserts & Sweets | C5: Approved source-of-truth taxonomy
A6: Food & Drink | B6: Food Trucks & Mobile Food | C6: Approved source-of-truth taxonomy
A7: Food & Drink | B7: Catering | C7: Approved source-of-truth taxonomy
A8: Food & Drink | B8: Bars & Lounges | C8: Approved source-of-truth taxonomy
A9: Food & Drink | B9: Juice & Smoothies | C9: Approved source-of-truth taxonomy
A10: Food & Drink | B10: Specialty Foods | C10: Approved source-of-truth taxonomy
A11: Food & Drink | B11: Meal Prep | C11: Approved source-of-truth taxonomy
A12: Food & Drink | B12: Grocery & Markets | C12: Approved source-of-truth taxonomy
... A286: Home & Property Services | B286: Mortgage & Homebuyer Counseling | C286: ADDED v2 — specialty/professional discovery gap

Sheet Vibe Reference
A1: Main Category | B1: Vibe Label | C1: Meaning / Helper Text | D1: Source | E1: Replit Rule
A2: Food & Drink | B2: Date Night | C2: Worth getting cute for | D2: Existing specification | E2: Show only when category/subcategory is vibe-eligible
A3: Food & Drink | B3: Hood Classic | C3: Been here forever, still hits | D3: Existing specification | E3: Show only when category/subcategory is vibe-eligible
A4: Food & Drink | B4: Bougie Treat | C4: Payday / splurge spot | D4: Existing specification | E4: Show only when category/subcategory is vibe-eligible
A5: Food & Drink | B5: Family Reunion Energy | C5: Loud, warm, everybody's welcome | D5: Existing specification | E5: Show only when category/subcategory is vibe-eligible
A6: Food & Drink | B6: Sunday Best | C6: After-church energy | D6: Existing specification | E6: Show only when category/subcategory is vibe-eligible
A7: Food & Drink | B7: Late Night Vibes | C7: Open when you need it | D7: Existing specification | E7: Show only when category/subcategory is vibe-eligible
A8: Food & Drink | B8: Turn Up | C8: Music up, energy high | D8: Existing specification | E8: Show only when category/subcategory is vibe-eligible
A9: Food & Drink | B9: Cookout Approved | C9: Passes the family test | D9: Existing specification | E9: Show only when category/subcategory is vibe-eligible
A10: Food & Drink | B10: Like Home | C10: Familiar, comfortable, somebody's-kitchen energy | D10: Added | E10: Show only when category/subcategory is vibe-eligible
A11: Food & Drink | B11: Auntie Energy | C11: Warm service; somebody is making sure you're good | D11: Added | E11: Show only when category/subcategory is vibe-eligible
A12: Food & Drink | B12: Tía Energy | C12: Warm, familiar, lovingly involved | D12: Added | E12: Show only when category/subcategory is vibe-eligible
... A132: Other Services | B132: N/A — Use Endorsements, Not Vibes | C132: This category should rely on earned endorsements instead of atmosphere labels. | D132: System rule | E132: Do not render The Vibe by default

Sheet Ownership Reference
A1: Ownership Designation | B1: Use | C1: Rule
A2: Black / African American-Owned | B2: Selectable as Ownership 1 or Ownership 2 | C2: Self-identified / documented only; never infer from name, photo, location, or cuisine
A3: African-Owned | B3: Selectable as Ownership 1 or Ownership 2 | C3: Self-identified / documented only; never infer from name, photo, location, or cuisine
A4: West African-Owned | B4: Selectable as Ownership 1 or Ownership 2 | C4: Self-identified / documented only; never infer from name, photo, location, or cuisine
A5: Nigerian-Owned | B5: Selectable as Ownership 1 or Ownership 2 | C5: Self-identified / documented only; never infer from name, photo, location, or cuisine
A6: Ghanaian-Owned | B6: Selectable as Ownership 1 or Ownership 2 | C6: Self-identified / documented only; never infer from name, photo, location, or cuisine
A7: Liberian-Owned | B7: Selectable as Ownership 1 or Ownership 2 | C7: Self-identified / documented only; never infer from name, photo, location, or cuisine
A8: Sierra Leonean-Owned | B8: Selectable as Ownership 1 or Ownership 2 | C8: Self-identified / documented only; never infer from name, photo, location, or cuisine
A9: Senegalese-Owned | B9: Selectable as Ownership 1 or Ownership 2 | C9: Self-identified / documented only; never infer from name, photo, location, or cuisine
A10: Guinean-Owned | B10: Selectable as Ownership 1 or Ownership 2 | C10: Self-identified / documented only; never infer from name, photo, location, or cuisine
A11: Gambian-Owned | B11: Selectable as Ownership 1 or Ownership 2 | C11: Self-identified / documented only; never infer from name, photo, location, or cuisine
A12: Ivorian-Owned | B12: Selectable as Ownership 1 or Ownership 2 | C12: Self-identified / documented only; never infer from name, photo, location, or cuisine
... A91: Minority-Owned (general / legacy) | B91: Selectable as Ownership 1 or Ownership 2 | C91: Self-identified / documented only; never infer from name, photo, location, or cuisine

Sheet Quick Reviews
A1: Main Category | B1: Endorsement / Quick Review | C1: Type | D1: Subcategory Scope | E1: Helper Text | F1: Source
A2: Food & Drink | B2: Worth The Drive | C2: universal | D2: all | E2: You'd cross town for this | F2: Existing specification
A3: Food & Drink | B3: Portions With Love | C3: universal | D3: all | E3: They didn't skimp | F3: Existing specification
A4: Food & Drink | B4: Clean & Cared For | C4: universal | D4: all | E4: The space is kept right | F4: Existing specification
A5: Food & Drink | B5: Grandma Approved | C5: adaptive | D5: all | E5: She would approve of this food | F5: Existing specification
A6: Food & Drink | B6: Cooks Like Home | C6: adaptive | D6: Restaurants; Catering; Private Chefs; Meal Prep; Specialty Foods | E6: Tastes like somebody's kitchen | F6: Existing specification
A7: Food & Drink | B7: They Speak My Language | C7: adaptive | D7: all | E7: You can order comfortably | F7: Existing specification
A8: Food & Drink | B8: Seasoned Right | C8: specific | D8: Restaurants; Food Trucks & Mobile Food; Catering; Meal Prep; Private Chefs | E8: No bland plates here | F8: Existing specification
A9: Food & Drink | B9: Plate Came Correct | C9: specific | D9: Restaurants; Food Trucks & Mobile Food | E9: Looked and tasted like the picture | F9: Existing specification
A10: Food & Drink | B10: They Don't Rush The Recipe | C10: specific | D10: Restaurants; Bakeries; Specialty Foods | E10: Slow-cooked, done properly | F10: Existing specification
A11: Food & Drink | B11: Ask For The Special | C11: specific | D11: Restaurants; Food Trucks & Mobile Food; Bars & Lounges | E11: The off-menu move is the move | F11: Existing specification
A12: Food & Drink | B12: Recipe From The Motherland | C12: specific | D12: Restaurants; Bakeries; Specialty Foods; Grocery & Markets | E12: Traditional, not watered down | F12: Existing specification
... A336: Other Services | B336: Save Their Number | C336: recommendation | D336: all | E336: A provider worth keeping | F336: Added

Sheet Replit Source of Truth
A1: Mapping With Melanin™ — Permanent Business Taxonomy + Endorsement Source of Truth
A3: System | B3: Authoritative workbook tab
A4: Business taxonomy | B4: Category Reference
A5: Vibes | B5: Vibe Reference
A6: Ownership designations | B6: Ownership Reference
A7: One-tap endorsements | B7: Quick Reviews
A8: Entry/import model | B8: Business Intake
A9: Maximum ownership designations | B9: 2
A10: Negative public endorsements | B10: Never — route concerns to private feedback/report flow
A12: PASTE THIS INTO REPLIT
A13: PERMANENT SOURCE-OF-TRUTH REQUIREMENT — IMPORT AND PRESERVE Use the attached Mapping With Melanin™ MASTER Business Directory workbook as the authoritative taxonomy for business ingestion. DO NOT rely on Agent chat memory. 1. Import and preserve the exact Main Category → Subcategory relationships from the "Category Reference" sheet. 2. Import the exact Vibe labels, helper text, eligibility and source status from "Vibe Reference". 3. Import the ownership designations from "Ownership Reference". A listing may have up to TWO ownership designations. Ownership is self-identified/documented only. Never infer race, ethnicity, nationality, gender, LGBTQIA+ status, disability, veteran status, or immigration background from a name, image, neighborhood, cuisine, language, or model prediction. 4. Import the complete one-tap endorsement vocabulary from "Quick Reviews". Preserve the wording. Do not rewrite, sanitize, professionalize, merge, or replace culturally specific wording. 5. Endorsements are praise-only. Concerns and negative experiences route to the existing private feedback / safety report flow. 6. Candidate endorsements are driven by business category + subcategory. User identity must never determine which businesses or endorsement families are eligible. 7. Culturally adaptive labels may render according to the user's explicitly selected community-language preference, but all variants for the same tag family roll up to ONE underlying count. Never infer the preference. 8. Keep Vibes separate from endorsements. Vibes describe atmosphere/visit type; endorsements describe what the community praises about the business. 9. Business owners may not award themselves endorsements or earned recognition badges. 10. Store these files in version control and treat them as permanent product specifications: docs/product/business-taxonomy.md docs/product/vibe-taxonomy.md docs/product/ownership-designations.md docs/product/endorsement-system.md data/business_categories.json data/vibe_tags.json data/ownership_designations.json data/endorsement_tags_seed.json data/endorsement_tag_variants_seed.json BEFORE WRITING OR MIGRATING DATA: - Perform a read-only comparison of the current database/code values against this workbook. - Report every conflict, missing category, orphaned subcategory, duplicate tag, renamed tag, and unsupported ownership designation. - Do not delete or overwrite existing production data until founder approval. - Preserve original submitted category values for audit/traceability while mapping them to the standardized category/subcategory. - Confirm the import counts back to me before implementation.
A40: V2 — THE REAL PROFESSIONAL TRUST LAYER
A41: THE REAL is the permanent user-facing name for the professional trust layer. Do not rename it. Do not treat it as a Vibe. A profile gets THE REAL OR The Vibe, never both. "What stands out?" endorsements remain universal. Import the complete source-derived THE REAL rows from the "THE REAL Reference" sheet. Preserve migrated keys and historical counts in production. Rows marked ADDED v2 are deliberate proposed expansions and must remain distinguishable during the read-only audit. Professional/service categories using THE REAL: Legal & Government Services; Professional Services; Financial & Business Services; Home & Property Services; Automotive & Transportation; Technology & Digital Services; Pets & Animal Services; Other Services. Health & Wellness is subcategory-routed: clinical/care gets THE REAL; Fitness & Gyms, Personal Trainers, and Yoga & Pilates get The Vibe. Candidate tags are determined by category + subcategory only. Never infer a user's race, ethnicity, gender, immigration status, religion, disability, or other identity to decide what to show. Cultural-language variants may use an explicitly saved preference only. Before implementation: READ-ONLY audit current code/database against this workbook. Report missing categories/subcategories, misclassified tags, duplicate/renamed tags, orphaned historical counts, any THE REAL/The Vibe co-rendering, and any identity-inference logic. Do not delete/reinsert migrated tags and do not implement until founder approval.

Sheet _Subcategory Lists
A1: Food & Drink | B1: Beauty & Personal Care | C1: Health & Wellness | D1: Shopping & Retail | E1: Travel & Hospitality | F1: Arts, Culture & Entertainment | G1: Professional Services | H1: Home & Property Services | I1: Automotive & Transportation | J1: Events & Celebrations | K1: Education & Learning | L1: Children & Family | M1: Community & Nonprofit | N1: Faith & Spirituality | O1: Media & Creative Services | P1: Sports & Recreation | Q1: Pets & Animal Services | R1: Technology & Digital Services | S1: Financial & Business Services | T1: Legal & Government Services | U1: Agriculture & Specialty Producers | V1: Other Services
A2: Restaurants | B2: Hair Salons | C2: Primary Care & Medical Practices | D2: Clothing & Fashion | E2: Hotels & Resorts | F2: Museums | G2: Accounting & Tax | H2: Real Estate Agents & Brokers | I2: Auto Repair | J2: Event Planning | K2: Childcare & Daycare | L2: Childcare | M2: Nonprofits | N2: Churches | O2: Content Creators | P2: Sports Clubs | Q2: Veterinarians | R2: Software Companies | S2: Banks & Credit Unions | T2: Attorneys & Law Firms | U2: Farms | V2: Laundry & Dry Cleaning
A3: Cafés & Coffee | B3: Barbershops | C3: Dental | D3: Shoes & Accessories | E3: Bed & Breakfasts | F3: Galleries | G3: Legal Services | H3: Property Management | I3: Auto Detailing | J3: Wedding Planning | K3: Preschools | L3: Children's Activities | M3: Community Organizations | N3: Mosques | O3: Influencers / Cultural Ambassadors | P3: Recreational Centers | Q3: Pet Grooming | R3: App Developers | S3: Financial Advisors | T3: Mediation | U3: Farmers Markets | V3: Tailoring & Alterations
A4: Bakeries | B4: Braiders & Natural Hair | C4: Mental Wellness & Therapy | D4: Jewelry | E4: Vacation Rentals | F4: Cultural Centers | G4: Insurance | H4: Contractors | I4: Car Wash | J4: Event Venues | K4: Tutoring | L4: Indoor Play | M4: Foundations | N4: Synagogues | O4: Podcasts | P4: Coaches & Training | Q4: Pet Boarding | R4: Web Developers | S4: Bookkeeping | T4: Notary Services | U4: Urban Farms | V4: Shoe Repair
A5: Desserts & Sweets | B5: Nail Salons & Nail Artists | C5: Physical Therapy | D5: Gifts | E5: Travel Agencies & Advisors | F5: Performing Arts | G5: Financial Services | H5: Construction | I5: Tire Services | J5: Party Rentals | K5: Test Preparation | L5: Camps | M5: Mutual Aid | N5: Temples | O5: Radio | P5: Youth Sports | Q5: Dog Walking & Pet Sitting | R5: IT Support | S5: Tax Preparation | T5: Immigration Services | U5: Specialty Growers | V5: Locksmiths
A6: Food Trucks & Mobile Food | B6: Makeup Artists | C6: Chiropractic | D6: Home Décor | E6: Tour Operators | F6: Theaters | G6: Business Consulting | H6: Electricians | I6: Auto Dealers | J6: Decorators | K6: Colleges & Universities | L6: Family Entertainment | M6: Advocacy Organizations | N6: Spiritual Centers | O6: Publications & Magazines | P6: Golf | Q6: Pet Training | R6: Cybersecurity | S6: Lending & Financing | T6: Legal Document Services | U6: Floriculture | V6: Shipping & Mailing
A7: Catering | B7: Estheticians & Skincare | C7: Nutrition & Dietitians | D7: Furniture | E7: Tour Guides | F7: Music & Live Entertainment | G7: Marketing & Advertising | H7: Plumbing | I7: Auto Body & Collision | J7: Florists | K7: HBCUs | L7: Parenting Services | M7: Youth Organizations | N7: Faith-Based Organizations | O7: Writers & Authors | P7: Swimming | Q7: Pet Daycare | R7: AI & Automation | S7: Mortgage Services | T7: Government Offices | U7: Food Producers | V7: Storage
A8: Bars & Lounges | B8: Spas | C8: Fitness & Gyms | D8: Books & Bookstores | E8: Transportation Services | F8: DJs | G8: Public Relations | H8: HVAC | I8: Towing & Roadside Assistance | J8: Balloon Artists | K8: Trade & Vocational Schools | L8: Children's Parties | M8: Senior Services | N8: Religious Bookstores & Retail | O8: Photography | P8: Martial Arts | Q8: Pet Stores & Supplies | R8: SaaS | S8: Credit Services | T8: Public Services | U8: Beverage Producers | V8: Funeral & Memorial Services
A9: Juice & Smoothies | B9: Massage | C9: Personal Trainers | D9: Art & Collectibles | E9: Luggage & Travel Products | F9: Entertainment Venues | G9: Graphic Design & Branding | H9: Landscaping & Lawn Care | I9: Car Rental | J9: DJs & Entertainment | K9: Professional Training | L9: Youth Programs | M9: Community Centers | N9: Faith-Based Community Services | O9: Videography | P9: Dance & Movement | R9: Digital Products | S9: Business Funding | U9: Agricultural Products | V9: Personal Concierge
A10: Specialty Foods | B10: Lashes & Brows | C10: Yoga & Pilates | D10: Specialty Retail | E10: Travel Experiences | F10: Nightlife | G10: Web & App Development | H10: Cleaning Services | I10: Chauffeur & Private Driver | J10: Photographers | K10: Music Lessons | L10: Children's Retail | M10: Cultural Organizations | O10: Production Companies | P10: Outdoor Recreation | R10: Technology Consulting | S10: Investment Services | V10: Other
A11: Meal Prep | B11: Beauty Supply | C11: Wellness Centers | D11: Children's Retail | F11: Festivals | G11: IT & Technology Services | H11: Interior Design | I11: Transportation Companies | J11: Videographers | K11: Dance Schools | L11: Maternity & Baby Services | M11: Professional Associations | O11: Recording Studios | P11: Adventure Experiences
A12: Grocery & Markets | B12: Cosmetics & Beauty Brands | C12: Doula & Birth Services | D12: Pet Products | F12: Attractions | G12: Printing | H12: Moving Services | J12: Caterers | K12: Art Classes | M12: Chambers & Business Organizations | O12: Music Production
A13: Private Chefs | B13: Mobile Beauty Services | C13: Holistic Wellness | D13: Online Shops | F13: Gaming & Recreation | G13: Translation & Language Services | H13: Handyman Services | J13: Cakes & Desserts | K13: Language Instruction | O13: Creative Studios
C14: Pharmacies | F14: Photography | G14: Staffing & Recruiting | H14: Home Inspection | J14: Invitations & Stationery | K14: Educational Programs
C15: Home Health & Caregiving | F15: Videography | G15: Virtual Assistants | H15: Roofing | J15: Photo Booths
H16: Pest Control

Sheet _Vibe Lists
A1: Food & Drink | B1: Beauty & Personal Care | C1: Health & Wellness | D1: Shopping & Retail | E1: Travel & Hospitality | F1: Arts, Culture & Entertainment | G1: Professional Services | H1: Home & Property Services | I1: Automotive & Transportation | J1: Events & Celebrations | K1: Education & Learning | L1: Children & Family | M1: Community & Nonprofit | N1: Faith & Spirituality | O1: Media & Creative Services | P1: Sports & Recreation | Q1: Pets & Animal Services | R1: Technology & Digital Services | S1: Financial & Business Services | T1: Legal & Government Services | U1: Agriculture & Specialty Producers | V1: Other Services
A2: Date Night | B2: Soft Life | C2: Chill & Restore | D2: Hood Classic | E2: Romantic Escape | F2: Date Night | G2: N/A — Use Endorsements, Not Vibes | H2: N/A — Use Endorsements, Not Vibes | I2: N/A — Use Endorsements, Not Vibes | J2: Family Reunion Energy | K2: Teach The Kids | L2: Kid Chaos Friendly | M2: Neighborhood Love | N2: Sunday Best | O2: Creative Scene | P2: Turn Up | Q2: N/A — Use Endorsements, Not Vibes | R2: N/A — Use Endorsements, Not Vibes | S2: N/A — Use Endorsements, Not Vibes | T2: N/A — Use Endorsements, Not Vibes | U2: Grand Rising | V2: N/A — Use Endorsements, Not Vibes
A3: Hood Classic | B3: Auntie Energy | C3: Peaceful Energy | D3: Locals Know | E3: Family Reunion Energy | F3: Turn Up | J3: Sunday Best | K3: Come As You Are | L3: Family Reunion Energy | M3: For The Culture | N3: Come As You Are | O3: Chill & Create | P3: Family Reunion Energy | U3: Family Reunion Energy
A4: Bougie Treat | B4: Tía Energy | C4: Come As You Are | D4: Hidden Gem | E4: Solo Traveler Comfortable | F4: Grown & Sexy | J4: Turn Up | K4: Creative Energy | L4: Rainy Day Rescue | M4: Come As You Are | N4: Quiet & Prayerful | O4: Main Character Energy | P4: Chill & Move | U4: Chill & Create
A5: Family Reunion Energy | B5: Main Character Energy | C5: Auntie Energy | D5: Bougie Treat | E5: Bougie Treat | F5: Hood Classic | J5: Grown & Sexy | K5: Community Classroom | L5: Toddler Safe | M5: Everybody Knows Somebody | N5: Praise Break Energy | O5: For The Culture | P5: Early Bird Energy | U5: Bring The Cousins
A6: Sunday Best | B6: Sunday Best | C6: Family Care | D6: Chill & Create | E6: Chill & Restore | F6: Chill & Create | J6: Bougie Treat | L6: Big Kid Approved | M6: Family Reunion Energy | N6: Family Worship | O6: Grown & Sexy | P6: Kid Chaos Friendly | U6: Hood Classic
A7: Late Night Vibes | B7: Chill & Restore | C7: Wellness Reset | D7: Bring The Cousins | E7: Girls Trip Ready | F7: Late Night Vibes | J7: Kid Chaos Friendly | L7: Parents Can Breathe | M7: History Lives Here | N7: Young Adult Friendly | P7: Adventure Ready | U7: Cookout Approved
A8: Turn Up | B8: Come As You Are | D8: For The Culture | E8: Grand Rising | F8: Family Reunion Energy | J8: Late Night Vibes | L8: Birthday Party Ready | N8: Auntie Energy | P8: Bring The Cousins | U8: Locals Know
A9: Cookout Approved | B9: For The Culture | D9: Take Somebody From Out of Town | E9: Bring The Cousins | F9: Sunday Best | J9: Cookout Approved | L9: Bring The Cousins | N9: Everybody Knows Somebody | U9: Teach The Kids
A10: Like Home | B10: Neighborhood Love | E10: Passport Energy | F10: History Lives Here | J10: Made For Memories | L10: Teach The Kids
A11: Auntie Energy | B11: Luxury Without The Attitude | E11: Take Somebody From Out of Town | F11: Culture On The Walls | J11: Bring The Cousins | L11: Like Home
A12: Tía Energy | E12: Luxury Without The Attitude | F12: Teach The Kids | J12: Luxury Without The Attitude
A13: Abuela Approved Energy | E13: Locals Know | F13: Creative Scene
A14: Soft Life
A15: Take Somebody From Out of Town
A16: Locals Know
A17: Passport Energy

Sheet _Quick Review Matrix
A1: Food & Drink | B1: Beauty & Personal Care | C1: Health & Wellness | D1: Shopping & Retail | E1: Travel & Hospitality | F1: Arts, Culture & Entertainment | G1: Professional Services | H1: Home & Property Services | I1: Automotive & Transportation | J1: Events & Celebrations | K1: Education & Learning | L1: Children & Family | M1: Community & Nonprofit | N1: Faith & Spirituality | O1: Media & Creative Services | P1: Sports & Recreation | Q1: Pets & Animal Services | R1: Technology & Digital Services | S1: Financial & Business Services | T1: Legal & Government Services | U1: Agriculture & Specialty Producers | V1: Other Services
A2: Worth The Drive | B2: On Time, Every Time | C2: Didn't Rush Me | D2: Quality Held Up | E2: Exactly As Pictured | F2: Worth The Ticket | G2: Straight With Me | H2: Showed Up When They Said | I2: Fair Price | J2: Delivered Exactly What I Asked | K2: My Child Improved | L2: Clean & Safe | M2: Help Was Real | N2: All Are Welcome (And Mean It) | O2: Delivered On Deadline | P2: Well Kept Facility | Q2: Gentle Hands | R2: Delivered What Was Promised | S2: Straight With Me | T2: Answered The Phone | U2: Fresh & Honest | V2: Fast & Reliable
A3: Portions With Love | B3: Clean Station | C3: Took Time To Explain | D3: Fair Prices | E3: Spotless | F3: Staff Was Welcoming | G3: Delivered On Time | H3: Cleaned Up After | I3: Fast Turnaround | J3: On Time Setup | K3: Teachers Actually Care | L3: Staff Was Patient | M3: No Judgment | N3: Visitors Feel At Home | O3: Easy To Work With | P3: Coaches Show Up | Q3: Fair Price | R3: Responsive | S3: No Hidden Fees | T3: Clear About Cost | U3: Fair Prices | V3: Fair Price
A4: Clean & Cared For | B4: Worth The Price | C4: Made Me Feel Heard | D4: No Follow-Around | E4: Worth The Stay | F4: Bring A Friend | G4: Answered The Phone | H4: Quote Matched The Bill | I4: Explained The Repair | J4: Worth Every Dollar | K4: Communication Was Clear | L4: Fair Price For Families | M4: Answered When I Called | N4: No Pressure, Just Peace | O4: Worth The Investment | P4: Fair Fees | Q4: Clean Facility | R4: Fair Scope & Price | S4: Answered The Phone | T4: On Time & Prepared | U4: Friendly Growers | V4: Careful With My Things
A5: Grandma Approved | B5: Blessed Hands | C5: Treated Me Like Family | D5: Grandma Approved | E5: Treated Me Like Family | F5: For The Culture | G5: Treated Me Like Family | H5: Treated Me Like Family | I5: Unc Trusts This Shop | J5: Sunday Best Ready | K5: Grandma Approved | L5: Grandma Approved | M5: Treated Me Like Family | N5: Mothers Of The Church Approve | O5: For The Culture | P5: For The Culture | Q5: Treated Me Like Family | R5: For The Culture | S5: Grandma Trusts Them | T5: They Speak My Language | U5: Grandma Approved | V5: Treated Me Like Family
A6: Cooks Like Home | B6: They Know Our Hair | C6: They Speak My Language | D6: For The Culture | E6: They Speak My Language | F6: Grandma Approved | G6: They Speak My Language | H6: Grandma Approved | I6: Treated Me Like Family | J6: Treated Me Like Family | K6: For The Culture | L6: For The Culture | M6: For The Culture | N6: They Speak My Language | O6: Blessed Hands | P6: Grandma Approved | Q6: Blessed Hands | R6: Treated Me Like Family | S6: Treated Me Like Family | T6: Treated Me Like Family | U6: Grows What We Cook | V6: Grandma Approved
A7: They Speak My Language | B7: Grandma Approved | C7: Grandma Trusts Them | D7: Treated Me Like Family | E7: For The Culture | F7: Sunday Best Ready | G7: For The Culture | H7: They Speak My Language | I7: They Speak My Language | J7: For The Culture | K7: They Speak My Language | L7: They Get Our Hair | M7: Elders Are Honored | N7: For The Culture | O7: Treated Me Like Family | P7: Treated Me Like Family | Q7: They Speak My Language | R7: They Speak My Language | S7: They Speak My Language | T7: For The Culture | U7: For The Culture | V7: Blessed Hands
A8: Seasoned Right | B8: Sharpest Lineup | C8: This Doctor Listens | D8: Found My Size | E8: Felt Safe The Whole Time | F8: Our Story Told Right | G8: Explained It Plain | H8: Didn't Talk Down To Me | I8: Didn't Upsell Me | J8: Handled My Whole Day | K8: My Kids See Themselves | L8: My Kids See Themselves | M8: Showed Up For The Block | N8: The Spirit Lives Here | O8: Told My Story Right | P8: Coach Builds Character | Q8: My Dog Wasn't Scared | R8: Explained It Without The Jargon | S8: Said Yes When Others Said No | T8: Fought For Me | U8: Picked This Morning | V8: Nothing Lost, Nothing Damaged
A9: Plate Came Correct | B9: Braids Didn't Hurt | C9: Believed My Pain | D9: Found My Shade | E9: Host Checked On Me | F9: DJ Read The Room | G9: No Surprise Fees | H9: Fixed It Right The First Time | I9: Showed Me The Old Part | J9: Vendor Team Was Smooth | K9: Taught Our History Right | L9: Culturally Affirming | M9: Hires From The Neighborhood | N9: Felt The Ancestors | O9: Lit My Skin Correctly | P9: Every Kid Plays | Q9: Honest About Treatment Cost | R9: Didn't Talk Down To Me | S9: Explained My Credit Plain | T9: Explained My Rights | U9: Seeds From Home | V9: Alterations Were Perfect
A10: They Don't Rush The Recipe | B10: Edges Respected | C10: Culturally Competent Care | D10: Owner Remembers Me | E10: Real Local Recommendations | F10: Artists Paid Fairly | G10: Fought For Me | H10: Respected My Home | I10: Safe For Women Coming Alone | J10: Florals Were Fresh | K10: Didn't Give Up On My Child | L10: Safe For My Baby | M10: No Hoops To Jump Through | N10: Community Not Just Congregation | O10: Sound Was Crisp | P10: Safe Space For Girls | Q10: Payment Plan Offered | R10: Handed Over The Passwords | S10: No Predatory Terms | T10: Didn't Take My Money And Ghost | U10: Takes EBT / SNAP | V10: Brought My Shoes Back To Life
A11: Ask For The Special | B11: Style Lasted | C11: Understands My Skin | D11: Shelves Reflect Us | E11: Hair-Friendly Water & Towels | F11: Kids Left Inspired | G11: Saved Me Money | H11: Honest About What I Didn't Need | I11: Loaner Or Ride Home Offered | J11: Cake Tasted As Good As It Looked | K11: Discipline Without Disrespect | L11: Diverse Staff | M11: Youth Are Valued | N11: Leadership Knows Your Name | O11: Didn't Steal My Vision | P11: Beginners Welcome | Q11: Groom Was Exactly Right | R11: Site Actually Loads Fast | S11: Got Me Funded | T11: Payment Plan Offered | U11: Land Back In Our Hands | V11: Came Out At 2AM
A12: Recipe From The Motherland | B12: My Shade Was There | C12: Understands My Hair | D12: Wrapped With Care | E12: Breakfast Hit | F12: Free Day Is Real | G12: Took My Small Business Seriously | H12: Warranty Was Real | I12: Detail Was Immaculate | J12: Captured The Real Moments | K12: Financial Aid Help Was Real | L12: My Child Wants To Go Back | M12: Money Reached The People | N12: Youth Are Valued | O12: Paid Their Team | P12: No Ego In Here | Q12: Sent Photos While I Was Gone | R12: Fixed It Same Day | S12: Taught Me To Build Wealth | T12: Handled My Immigration Case With Care | U12: Teaches While Selling | V12: Handled Our Loss With Grace
... A15: Book This Table | B15: Patient With Kids | C15: Therapist Gets The Culture | D15: Take My Money | E15: Driver Was Solid | F15: Got My Angles | G15: Didn't Talk Down To Me | H15: Helped Me Buy My First Home | I15: Driver Was Professional | J15: No Day-Of Drama | K15: Culturally Affirming Curriculum | L15: Never Pushed My Child Out | M15: Advocated At City Hall | N15: Choir Sent Me | O15: Made Me Look Like Me | P15: Discipline With Love | Q15: Save This Vet / Groomer | R15: Hire Them | S15: Free Consult Was Actually Free | T15: Kept My Family Together | U15: Shop Here Before The Cookout | V15: Dry & Secure
A16: Don't Sleep On This One | B16: Book Now | C16: Doula Held Me Down | D16: Don't Leave Without It | E16: Book This Stay | F16: Put This On The Calendar | G16: Hire Them | H16: Actually Fixes Things | I16: Save This Shop | J16: Book Them | K16: Send Your People Here | L16: Parents Put This On The List | M16: Share This Resource | N16: Leader Made Time For Me | O16: Book Them | P16: Taught Me To Swim At Any Age | S16: Send Your People Here | T16: Call Them | V16: Save Their Number
A17: I Sent The Group Chat | B17: Ask For Them By Name | C17: Prices Were Clear Up Front | E17: Add It To The Trip | H17: Save Their Number | N17: Bring Somebody With You | P17: Sign Up
C18: No Judgment About My Body

Sheet THE REAL Reference
A1: Main Category | B1: THE REAL Tag | C1: Type | D1: Subcategory Scope | E1: Helper Text | F1: Origin | G1: Source
A2: Health & Wellness | B2: This Doctor Listens | C2: real-specific | D2: primary care, dental, PT, chiropractic, holistic | E2: They asked, then waited for the whole answer | F2: migrate | G2: Founder PDF p.14
A3: Health & Wellness | B3: Believed My Pain | C3: real-specific | D3: primary care, dental, PT, chiropractic, doula | E3: No minimizing, no doubting, no "are you sure?" | F3: migrate | G3: Founder PDF p.14
A4: Health & Wellness | B4: Believed Me | C4: real-adaptive | D4: all real subcats | E4: They took your account of your own body as true | F4: new | G4: Founder PDF p.14
A5: Health & Wellness | B5: Culturally Competent Care | C5: real-specific | D5: all real subcats | E5: They understand where you come from | F5: migrate | G5: Founder PDF p.14
A6: Health & Wellness | B6: Understands My Skin | C6: real-specific | D6: primary care (dermatology) , wellness centers | E6: Trained on melanated skin, not just textbook photos | F6: migrate | G6: Founder PDF p.14
A7: Health & Wellness | B7: Understands My Hair | C7: real-specific | D7: primary care (dermatology) , wellness centers | E7: Knows textured hair and scalp conditions | F7: migrate | G7: Founder PDF p.14
A8: Health & Wellness | B8: Fought For My Coverage | C8: real-specific | D8: all real subcats | E8: They pushed insurance so you didn't have to | F8: migrate | G8: Founder PDF p.14
A9: Health & Wellness | B9: Knew My Condition Hits Us Different | C9: real-adaptive ( knows_what_ | D9: primary care, dental, PT, chiropractic, holistic, doula | E9: They knew the numbers for our community without being told | F9: new | G9: Founder PDF p.14
A10: Health & Wellness | B10: Didn't Dismiss My Symptoms | C10: real-specific | D10: all real subcats | E10: What you reported was investigated, not filed away | F10: new | G10: Founder PDF p.15
A11: Health & Wellness | B11: Explained Options, Not Just Orders | C11: real-specific | D11: all real subcats | E11: You chose your care, you weren't handed a decision | F11: new | G11: Founder PDF p.15
A12: Health & Wellness | B12: Waited For My Questions | C12: real-specific | D12: all real subcats | E12: Nobody had a hand on the doorknob | F12: new | G12: Founder PDF p.15
... A152: Home & Property Services | B152: Explained First-Time Buyer Programs | C152: real-specific | D152: Real Estate Agents & Brokers; Housing Counselors; Mortgage & Homebuyer Counseling | E152: They showed me assistance and programs I might qualify for | F152: ADDED v2 | G152: Suggested addition

Sheet Layer Routing
A1: Category / Subcategory | B1: Layer | C1: Rule
A2: Food, retail, travel, arts, events, family, faith, recreation and other experience categories | B2: The Vibe | C2: Atmosphere/visit type; What stands out? remains universal
A3: Health & Wellness — clinical/care | B3: THE REAL | C3: Primary care, dental, therapy, PT, chiropractic, nutrition, wellness centers, doula/birth, holistic, pharmacy, home health + v2 clinical specialties
A4: Health & Wellness — Fitness & Gyms / Personal Trainers / Yoga & Pilates | B4: The Vibe | C4: Movement/wellness experience exception
A5: Legal & Government Services | B5: THE REAL | C5: Professional trust
A6: Professional Services | B6: THE REAL | C6: Professional trust
A7: Financial & Business Services | B7: THE REAL | C7: Professional trust
A8: Home & Property Services | B8: THE REAL | C8: Professional/service trust
A9: Automotive & Transportation | B9: THE REAL | C9: Professional/service trust
A10: Technology & Digital Services | B10: THE REAL | C10: Professional/service trust
A11: Pets & Animal Services | B11: THE REAL | C11: Professional/service trust
A12: Other Services | B12: THE REAL | C12: Professional/service trust

Sheet Business Intake v2
A1: Business Name | B1: City | C1: State | D1: Original Category | E1: Main Category | F1: Subcategory | G1: Website or Social Media | H1: Brief Description (1–2 sentences) | I1: Profile Layer | J1: Vibe 1 (if applicable) | K1: Vibe 2 (if applicable) | L1: Vibe 3 (if applicable) | M1: THE REAL 1 (if applicable) | N1: THE REAL 2 (if applicable) | O1: THE REAL 3 (if applicable) | P1: Ownership 1 | Q1: Ownership 2 | R1: Recommended By | S1: Notes | T1: Address | U1: Zip Code | V1: What Stands Out? 1 | W1: What Stands Out? 2 | X1: What Stands Out? 3 | Y1: Verification Status | AA1: HOW THIS INTAKE WORKS
A2: The Nail Jawns | B2: Philadelphia | C2: PA | D2: Nail Salon | E2: Beauty & Personal Care | F2: Nail Salons & Nail Artists | G2: https://www.tiktok.com/@the.nail.jawns | I2: =IFERROR(INDEX('_Layer Lookup v3'!$B$2:$B$267,MATCH($E2&"|"&$F2,'_Layer Lookup v3'!$A$2:$A$267,0)),"") -> The Vibe | P2: Black / African American-Owned | R2: Friend | S2: Walk-ins Welcomed, Appointments preferred. | T2: 429 N. 64th St | U2: 19151 | AA2: 1) Choose Main Category. 2) Choose the matching Subcategory. 3) Profile Layer fills automatically: The Vibe OR THE REAL. 4) Choose up to 3 applicable Vibes or THE REAL trust tags from the dependent dropdowns. 5) Choose up to 3 universal “What Stands Out?” one-tap endorsements. 6) Ownership 1 and 2 remain separate from category, Vibe, THE REAL, and endorsements.
A3: Cherished Beauty Supply | B3: Darby | C3: PA | D3: Beauty | E3: Beauty & Personal Care | F3: Beauty Supply | G3: https://www.tiktok.com/@cherishedbeautysupply | H3: Plant-Based Hair & Skin Care. Black-Owned Beauty Supply | I3: =IFERROR(INDEX('_Layer Lookup v3'!$B$2:$B$267,MATCH($E3&"|"&$F3,'_Layer Lookup v3'!$A$2:$A$267,0)),"") -> The Vibe | P3: Black / African American-Owned | R3: Friend | S3: Willing to Ship! | T3: 526 Main St | U3: 19023
A4: Angie's Eats | B4: Philadelphia | C4: PA | D4: Restaurant | E4: Food & Drink | F4: Restaurants | G4: https://www.tiktok.com/@angieslne | H4: Latin Soul Food | I4: =IFERROR(INDEX('_Layer Lookup v3'!$B$2:$B$267,MATCH($E4&"|"&$F4,'_Layer Lookup v3'!$A$2:$A$267,0)),"") -> The Vibe | P4: Latino / Hispanic-Owned | R4: Personal visit | S4: The Shrimp Alfredo with 6 wings combo is FIRE
A5: ISSAAESTHETICS Beauty Salon & Barbershop | B5: Silver Spring | C5: MD | D5: Barber/Salon | E5: Beauty & Personal Care | F5: Hair Salons | G5: https://www.instagram.com/issaaestheticsbeauty | H5: Laser Hair Removal/Blow Outs/Chemical Peels and More | I5: =IFERROR(INDEX('_Layer Lookup v3'!$B$2:$B$267,MATCH($E5&"|"&$F5,'_Layer Lookup v3'!$A$2:$A$267,0)),"") -> The Vibe | P5: Dominican-Owned | R5: Friend | S5: Se Habla Espanol | T5: 11409 Amherst Ave Unit A | U5: 20902
A6: Candy Clouds By Cass | B6: Santa Clara | C6: CA | D6: Restaurant | E6: Food & Drink | F6: Desserts & Sweets | G6: https://www.instagram.com/candycloudsbycass | H6: Sweet Clouds for Every Celebration! | I6: =IFERROR(INDEX('_Layer Lookup v3'!$B$2:$B$267,MATCH($E6&"|"&$F6,'_Layer Lookup v3'!$A$2:$A$267,0)),"") -> The Vibe | P6: Minority-Owned (general / legacy) | S6: Serving the Bay Area
A7: Little Essentials | B7: New York | C7: NY | E7: Children & Family | F7: Children's Retail | I7: =IFERROR(INDEX('_Layer Lookup v3'!$B$2:$B$267,MATCH($E7&"|"&$F7,'_Layer Lookup v3'!$A$2:$A$267,0)),"") -> The Vibe
I8: =IFERROR(INDEX('_Layer Lookup v3'!$B$2:$B$267,MATCH($E8&"|"&$F8,'_Layer Lookup v3'!$A$2:$A$267,0)),"")
I9: =IFERROR(INDEX('_Layer Lookup v3'!$B$2:$B$267,MATCH($E9&"|"&$F9,'_Layer Lookup v3'!$A$2:$A$267,0)),"")
I10: =IFERROR(INDEX('_Layer Lookup v3'!$B$2:$B$267,MATCH($E10&"|"&$F10,'_Layer Lookup v3'!$A$2:$A$267,0)),"")
I11: =IFERROR(INDEX('_Layer Lookup v3'!$B$2:$B$267,MATCH($E11&"|"&$F11,'_Layer Lookup v3'!$A$2:$A$267,0)),"")
I12: =IFERROR(INDEX('_Layer Lookup v3'!$B$2:$B$267,MATCH($E12&"|"&$F12,'_Layer Lookup v3'!$A$2:$A$267,0)),"")
I13: =IFERROR(INDEX('_Layer Lookup v3'!$B$2:$B$267,MATCH($E13&"|"&$F13,'_Layer Lookup v3'!$A$2:$A$267,0)),"")
I14: =IFERROR(INDEX('_Layer Lookup v3'!$B$2:$B$267,MATCH($E14&"|"&$F14,'_Layer Lookup v3'!$A$2:$A$267,0)),"")
I15: =IFERROR(INDEX('_Layer Lookup v3'!$B$2:$B$267,MATCH($E15&"|"&$F15,'_Layer Lookup v3'!$A$2:$A$267,0)),"")
I16: =IFERROR(INDEX('_Layer Lookup v3'!$B$2:$B$267,MATCH($E16&"|"&$F16,'_Layer Lookup v3'!$A$2:$A$267,0)),"")
I17: =IFERROR(INDEX('_Layer Lookup v3'!$B$2:$B$267,MATCH($E17&"|"&$F17,'_Layer Lookup v3'!$A$2:$A$267,0)),"")
I18: =IFERROR(INDEX('_Layer Lookup v3'!$B$2:$B$267,MATCH($E18&"|"&$F18,'_Layer Lookup v3'!$A$2:$A$267,0)),"")
I19: =IFERROR(INDEX('_Layer Lookup v3'!$B$2:$B$267,MATCH($E19&"|"&$F19,'_Layer Lookup v3'!$A$2:$A$267,0)),"")
... I500: =IFERROR(INDEX('_Layer Lookup v3'!$B$2:$B$267,MATCH($E500&"|"&$F500,'_Layer Lookup v3'!$A$2:$A$267,0)),"")

Sheet _Subcategory Dropdowns v3
A1: Food & Drink | B1: Beauty & Personal Care | C1: Health & Wellness | D1: Shopping & Retail | E1: Travel & Hospitality | F1: Arts, Culture & Entertainment | G1: Professional Services | H1: Home & Property Services | I1: Automotive & Transportation | J1: Events & Celebrations | K1: Education & Learning | L1: Children & Family | M1: Community & Nonprofit | N1: Faith & Spirituality | O1: Media & Creative Services | P1: Sports & Recreation | Q1: Pets & Animal Services | R1: Technology & Digital Services | S1: Financial & Business Services | T1: Legal & Government Services | U1: Agriculture & Specialty Producers | V1: Other Services
A2: Restaurants | B2: Hair Salons | C2: Primary Care & Medical Practices | D2: Clothing & Fashion | E2: Hotels & Resorts | F2: Museums | G2: Accounting & Tax | H2: Real Estate Agents & Brokers | I2: Auto Repair | J2: Event Planning | K2: Childcare & Daycare | L2: Childcare | M2: Nonprofits | N2: Churches | O2: Content Creators | P2: Sports Clubs | Q2: Veterinarians | R2: Software Companies | S2: Banks & Credit Unions | T2: Attorneys & Law Firms | U2: Farms | V2: Laundry & Dry Cleaning
A3: Cafés & Coffee | B3: Barbershops | C3: Dental | D3: Shoes & Accessories | E3: Bed & Breakfasts | F3: Galleries | G3: Legal Services | H3: Property Management | I3: Auto Detailing | J3: Wedding Planning | K3: Preschools | L3: Children's Activities | M3: Community Organizations | N3: Mosques | O3: Influencers / Cultural Ambassadors | P3: Recreational Centers | Q3: Pet Grooming | R3: App Developers | S3: Financial Advisors | T3: Mediation | U3: Farmers Markets | V3: Tailoring & Alterations
A4: Bakeries | B4: Braiders & Natural Hair | C4: Mental Wellness & Therapy | D4: Jewelry | E4: Vacation Rentals | F4: Cultural Centers | G4: Insurance | H4: Contractors | I4: Car Wash | J4: Event Venues | K4: Tutoring | L4: Indoor Play | M4: Foundations | N4: Synagogues | O4: Podcasts | P4: Coaches & Training | Q4: Pet Boarding | R4: Web Developers | S4: Bookkeeping | T4: Notary Services | U4: Urban Farms | V4: Shoe Repair
A5: Desserts & Sweets | B5: Nail Salons & Nail Artists | C5: Physical Therapy | D5: Gifts | E5: Travel Agencies & Advisors | F5: Performing Arts | G5: Financial Services | H5: Construction | I5: Tire Services | J5: Party Rentals | K5: Test Preparation | L5: Camps | M5: Mutual Aid | N5: Temples | O5: Radio | P5: Youth Sports | Q5: Dog Walking & Pet Sitting | R5: IT Support | S5: Tax Preparation | T5: Immigration Services | U5: Specialty Growers | V5: Locksmiths
A6: Food Trucks & Mobile Food | B6: Makeup Artists | C6: Chiropractic | D6: Home Décor | E6: Tour Operators | F6: Theaters | G6: Business Consulting | H6: Electricians | I6: Auto Dealers | J6: Decorators | K6: Colleges & Universities | L6: Family Entertainment | M6: Advocacy Organizations | N6: Spiritual Centers | O6: Publications & Magazines | P6: Golf | Q6: Pet Training | R6: Cybersecurity | S6: Lending & Financing | T6: Legal Document Services | U6: Floriculture | V6: Shipping & Mailing
A7: Catering | B7: Estheticians & Skincare | C7: Nutrition & Dietitians | D7: Furniture | E7: Tour Guides | F7: Music & Live Entertainment | G7: Marketing & Advertising | H7: Plumbing | I7: Auto Body & Collision | J7: Florists | K7: HBCUs | L7: Parenting Services | M7: Youth Organizations | N7: Faith-Based Organizations | O7: Writers & Authors | P7: Swimming | Q7: Pet Daycare | R7: AI & Automation | S7: Mortgage Services | T7: Government Offices | U7: Food Producers | V7: Storage
A8: Bars & Lounges | B8: Spas | C8: Fitness & Gyms | D8: Books & Bookstores | E8: Transportation Services | F8: DJs | G8: Public Relations | H8: HVAC | I8: Towing & Roadside Assistance | J8: Balloon Artists | K8: Trade & Vocational Schools | L8: Children's Parties | M8: Senior Services | N8: Religious Bookstores & Retail | O8: Photography | P8: Martial Arts | Q8: Pet Stores & Supplies | R8: SaaS | S8: Credit Services | T8: Public Services | U8: Beverage Producers | V8: Funeral & Memorial Services
A9: Juice & Smoothies | B9: Massage | C9: Personal Trainers | D9: Art & Collectibles | E9: Luggage & Travel Products | F9: Entertainment Venues | G9: Graphic Design & Branding | H9: Landscaping & Lawn Care | I9: Car Rental | J9: DJs & Entertainment | K9: Professional Training | L9: Youth Programs | M9: Community Centers | N9: Faith-Based Community Services | O9: Videography | P9: Dance & Movement | R9: Digital Products | S9: Business Funding | T9: Immigration Attorneys | U9: Agricultural Products | V9: Personal Concierge
A10: Specialty Foods | B10: Lashes & Brows | C10: Yoga & Pilates | D10: Specialty Retail | E10: Travel Experiences | F10: Nightlife | G10: Web & App Development | H10: Cleaning Services | I10: Chauffeur & Private Driver | J10: Photographers | K10: Music Lessons | L10: Children's Retail | M10: Cultural Organizations | O10: Production Companies | P10: Outdoor Recreation | R10: Technology Consulting | S10: Investment Services | T10: Family Law | V10: Other
A11: Meal Prep | B11: Beauty Supply | C11: Wellness Centers | D11: Children's Retail | F11: Festivals | G11: IT & Technology Services | H11: Interior Design | I11: Transportation Companies | J11: Videographers | K11: Dance Schools | L11: Maternity & Baby Services | M11: Professional Associations | O11: Recording Studios | P11: Adventure Experiences | S11: Small Business Banking | T11: Criminal Defense
A12: Grocery & Markets | B12: Cosmetics & Beauty Brands | C12: Doula & Birth Services | D12: Pet Products | F12: Attractions | G12: Printing | H12: Moving Services | J12: Caterers | K12: Art Classes | M12: Chambers & Business Organizations | O12: Music Production | S12: Community Development Financial Institutions (CDFIs) | T12: Civil Rights
A13: Private Chefs | B13: Mobile Beauty Services | C13: Holistic Wellness | D13: Online Shops | F13: Gaming & Recreation | G13: Translation & Language Services | H13: Handyman Services | J13: Cakes & Desserts | K13: Language Instruction | O13: Creative Studios | S13: SBA & Business Loan Services | T13: Employment Law
C14: Pharmacies | F14: Photography | G14: Staffing & Recruiting | H14: Home Inspection | J14: Invitations & Stationery | K14: Educational Programs | T14: Housing & Tenant Law
C15: Home Health & Caregiving | F15: Videography | G15: Virtual Assistants | H15: Roofing | J15: Photo Booths | T15: Estate Planning & Probate
C16: OB-GYN & Women's Health | G16: Career Coaching | H16: Pest Control | T16: Personal Injury
C17: Pediatrics | G17: Executive Coaching | H17: Housing Counselors | T17: Business Law
C18: Dermatology | G18: Grant Writing | H18: Mortgage & Homebuyer Counseling
C19: Cardiology | G19: Procurement & Government Contracting
C20: Maternal-Fetal Medicine
C21: Midwifery
C22: Fertility & Reproductive Health
C23: Urgent Care
C24: Specialist Physicians

Sheet _Vibe Dropdowns v3
A1: Category|Subcategory | B1: Option 1 | C1: Option 2 | D1: Option 3 | E1: Option 4 | F1: Option 5 | G1: Option 6 | H1: Option 7 | I1: Option 8 | J1: Option 9 | K1: Option 10 | L1: Option 11 | M1: Option 12 | N1: Option 13 | O1: Option 14 | P1: Option 15 | Q1: Option 16 | R1: Option 17 | S1: Option 18 | T1: Option 19 | U1: Option 20 | V1: Option 21 | W1: Option 22 | X1: Option 23 | Y1: Option 24 | Z1: Option 25 | AA1: Option 26 | AB1: Option 27 | AC1: Option 28 | AD1: Option 29 | AE1: Option 30 | AF1: Option 31 | AG1: Option 32 | AH1: Option 33 | AI1: Option 34 | AJ1: Option 35 | AK1: Option 36 | AL1: Option 37 | AM1: Option 38 | AN1: Option 39 | AO1: Option 40 | AP1: Option 41 | AQ1: Option 42 | AR1: Option 43 | AS1: Option 44 | AT1: Option 45 | AU1: Option 46 | AV1: Option 47 | AW1: Option 48 | AX1: Option 49 | AY1: Option 50 | AZ1: Option 51
A2: Food & Drink|Restaurants | B2: Date Night | C2: Hood Classic | D2: Bougie Treat | E2: Family Reunion Energy | F2: Sunday Best | G2: Late Night Vibes | H2: Turn Up | I2: Cookout Approved | J2: Like Home | K2: Auntie Energy | L2: Tía Energy | M2: Abuela Approved Energy | N2: Soft Life | O2: Take Somebody From Out of Town | P2: Locals Know | Q2: Passport Energy
A3: Food & Drink|Cafés & Coffee | B3: Date Night | C3: Hood Classic | D3: Bougie Treat | E3: Family Reunion Energy | F3: Sunday Best | G3: Late Night Vibes | H3: Turn Up | I3: Cookout Approved | J3: Like Home | K3: Auntie Energy | L3: Tía Energy | M3: Abuela Approved Energy | N3: Soft Life | O3: Take Somebody From Out of Town | P3: Locals Know | Q3: Passport Energy
A4: Food & Drink|Bakeries | B4: Date Night | C4: Hood Classic | D4: Bougie Treat | E4: Family Reunion Energy | F4: Sunday Best | G4: Late Night Vibes | H4: Turn Up | I4: Cookout Approved | J4: Like Home | K4: Auntie Energy | L4: Tía Energy | M4: Abuela Approved Energy | N4: Soft Life | O4: Take Somebody From Out of Town | P4: Locals Know | Q4: Passport Energy
A5: Food & Drink|Desserts & Sweets | B5: Date Night | C5: Hood Classic | D5: Bougie Treat | E5: Family Reunion Energy | F5: Sunday Best | G5: Late Night Vibes | H5: Turn Up | I5: Cookout Approved | J5: Like Home | K5: Auntie Energy | L5: Tía Energy | M5: Abuela Approved Energy | N5: Soft Life | O5: Take Somebody From Out of Town | P5: Locals Know | Q5: Passport Energy
A6: Food & Drink|Food Trucks & Mobile Food | B6: Date Night | C6: Hood Classic | D6: Bougie Treat | E6: Family Reunion Energy | F6: Sunday Best | G6: Late Night Vibes | H6: Turn Up | I6: Cookout Approved | J6: Like Home | K6: Auntie Energy | L6: Tía Energy | M6: Abuela Approved Energy | N6: Soft Life | O6: Take Somebody From Out of Town | P6: Locals Know | Q6: Passport Energy
A7: Food & Drink|Catering | B7: Date Night | C7: Hood Classic | D7: Bougie Treat | E7: Family Reunion Energy | F7: Sunday Best | G7: Late Night Vibes | H7: Turn Up | I7: Cookout Approved | J7: Like Home | K7: Auntie Energy | L7: Tía Energy | M7: Abuela Approved Energy | N7: Soft Life | O7: Take Somebody From Out of Town | P7: Locals Know | Q7: Passport Energy
A8: Food & Drink|Bars & Lounges | B8: Date Night | C8: Hood Classic | D8: Bougie Treat | E8: Family Reunion Energy | F8: Sunday Best | G8: Late Night Vibes | H8: Turn Up | I8: Cookout Approved | J8: Like Home | K8: Auntie Energy | L8: Tía Energy | M8: Abuela Approved Energy | N8: Soft Life | O8: Take Somebody From Out of Town | P8: Locals Know | Q8: Passport Energy
A9: Food & Drink|Juice & Smoothies | B9: Date Night | C9: Hood Classic | D9: Bougie Treat | E9: Family Reunion Energy | F9: Sunday Best | G9: Late Night Vibes | H9: Turn Up | I9: Cookout Approved | J9: Like Home | K9: Auntie Energy | L9: Tía Energy | M9: Abuela Approved Energy | N9: Soft Life | O9: Take Somebody From Out of Town | P9: Locals Know | Q9: Passport Energy
A10: Food & Drink|Specialty Foods | B10: Date Night | C10: Hood Classic | D10: Bougie Treat | E10: Family Reunion Energy | F10: Sunday Best | G10: Late Night Vibes | H10: Turn Up | I10: Cookout Approved | J10: Like Home | K10: Auntie Energy | L10: Tía Energy | M10: Abuela Approved Energy | N10: Soft Life | O10: Take Somebody From Out of Town | P10: Locals Know | Q10: Passport Energy
A11: Food & Drink|Meal Prep | B11: Date Night | C11: Hood Classic | D11: Bougie Treat | E11: Family Reunion Energy | F11: Sunday Best | G11: Late Night Vibes | H11: Turn Up | I11: Cookout Approved | J11: Like Home | K11: Auntie Energy | L11: Tía Energy | M11: Abuela Approved Energy | N11: Soft Life | O11: Take Somebody From Out of Town | P11: Locals Know | Q11: Passport Energy
A12: Food & Drink|Grocery & Markets | B12: Date Night | C12: Hood Classic | D12: Bougie Treat | E12: Family Reunion Energy | F12: Sunday Best | G12: Late Night Vibes | H12: Turn Up | I12: Cookout Approved | J12: Like Home | K12: Auntie Energy | L12: Tía Energy | M12: Abuela Approved Energy | N12: Soft Life | O12: Take Somebody From Out of Town | P12: Locals Know | Q12: Passport Energy
A13: Food & Drink|Private Chefs | B13: Date Night | C13: Hood Classic | D13: Bougie Treat | E13: Family Reunion Energy | F13: Sunday Best | G13: Late Night Vibes | H13: Turn Up | I13: Cookout Approved | J13: Like Home | K13: Auntie Energy | L13: Tía Energy | M13: Abuela Approved Energy | N13: Soft Life | O13: Take Somebody From Out of Town | P13: Locals Know | Q13: Passport Energy
A14: Beauty & Personal Care|Hair Salons | B14: Soft Life | C14: Auntie Energy | D14: Tía Energy | E14: Main Character Energy | F14: Sunday Best | G14: Chill & Restore | H14: Come As You Are | I14: For The Culture | J14: Neighborhood Love | K14: Luxury Without The Attitude
A15: Beauty & Personal Care|Barbershops | B15: Soft Life | C15: Auntie Energy | D15: Tía Energy | E15: Main Character Energy | F15: Sunday Best | G15: Chill & Restore | H15: Come As You Are | I15: For The Culture | J15: Neighborhood Love | K15: Luxury Without The Attitude
A16: Beauty & Personal Care|Braiders & Natural Hair | B16: Soft Life | C16: Auntie Energy | D16: Tía Energy | E16: Main Character Energy | F16: Sunday Best | G16: Chill & Restore | H16: Come As You Are | I16: For The Culture | J16: Neighborhood Love | K16: Luxury Without The Attitude
A17: Beauty & Personal Care|Nail Salons & Nail Artists | B17: Soft Life | C17: Auntie Energy | D17: Tía Energy | E17: Main Character Energy | F17: Sunday Best | G17: Chill & Restore | H17: Come As You Are | I17: For The Culture | J17: Neighborhood Love | K17: Luxury Without The Attitude
A18: Beauty & Personal Care|Makeup Artists | B18: Soft Life | C18: Auntie Energy | D18: Tía Energy | E18: Main Character Energy | F18: Sunday Best | G18: Chill & Restore | H18: Come As You Are | I18: For The Culture | J18: Neighborhood Love | K18: Luxury Without The Attitude
A19: Beauty & Personal Care|Estheticians & Skincare | B19: Soft Life | C19: Auntie Energy | D19: Tía Energy | E19: Main Character Energy | F19: Sunday Best | G19: Chill & Restore | H19: Come As You Are | I19: For The Culture | J19: Neighborhood Love | K19: Luxury Without The Attitude
A20: Beauty & Personal Care|Spas | B20: Soft Life | C20: Auntie Energy | D20: Tía Energy | E20: Main Character Energy | F20: Sunday Best | G20: Chill & Restore | H20: Come As You Are | I20: For The Culture | J20: Neighborhood Love | K20: Luxury Without The Attitude
A21: Beauty & Personal Care|Massage | B21: Soft Life | C21: Auntie Energy | D21: Tía Energy | E21: Main Character Energy | F21: Sunday Best | G21: Chill & Restore | H21: Come As You Are | I21: For The Culture | J21: Neighborhood Love | K21: Luxury Without The Attitude
A22: Beauty & Personal Care|Lashes & Brows | B22: Soft Life | C22: Auntie Energy | D22: Tía Energy | E22: Main Character Energy | F22: Sunday Best | G22: Chill & Restore | H22: Come As You Are | I22: For The Culture | J22: Neighborhood Love | K22: Luxury Without The Attitude
A23: Beauty & Personal Care|Beauty Supply | B23: Soft Life | C23: Auntie Energy | D23: Tía Energy | E23: Main Character Energy | F23: Sunday Best | G23: Chill & Restore | H23: Come As You Are | I23: For The Culture | J23: Neighborhood Love | K23: Luxury Without The Attitude
A24: Beauty & Personal Care|Cosmetics & Beauty Brands | B24: Soft Life | C24: Auntie Energy | D24: Tía Energy | E24: Main Character Energy | F24: Sunday Best | G24: Chill & Restore | H24: Come As You Are | I24: For The Culture | J24: Neighborhood Love | K24: Luxury Without The Attitude
A25: Beauty & Personal Care|Mobile Beauty Services | B25: Soft Life | C25: Auntie Energy | D25: Tía Energy | E25: Main Character Energy | F25: Sunday Best | G25: Chill & Restore | H25: Come As You Are | I25: For The Culture | J25: Neighborhood Love | K25: Luxury Without The Attitude
A26: Health & Wellness|Primary Care & Medical Practices | B26: N/A — This profile uses THE REAL
A27: Health & Wellness|Dental | B27: N/A — This profile uses THE REAL
A28: Health & Wellness|Mental Wellness & Therapy | B28: N/A — This profile uses THE REAL
A29: Health & Wellness|Physical Therapy | B29: N/A — This profile uses THE REAL
A30: Health & Wellness|Chiropractic | B30: N/A — This profile uses THE REAL
A31: Health & Wellness|Nutrition & Dietitians | B31: N/A — This profile uses THE REAL
